Workbook
Name SegmentaciónDeDatos_ACUM: #N/A
Name SegmentaciónDeDatos_FECHA: #N/A
Name SegmentaciónDeDatos_FECHA1: #N/A
Name SegmentaciónDeDatos_M_E: #N/A
Name SegmentaciónDeDatos_MAQUINA_AREA_EQUIPO: #N/A
Name SegmentaciónDeDatos_MAQUINA_AREA_EQUIPO1: #N/A
Name SegmentaciónDeDatos_P_NP: #N/A
Name SegmentaciónDeDatos_PIEZA___PARTE: #N/A
Name SegmentaciónDeDatos_TIPO_ACTIVIDAD: #N/A
Name Tecnicos: DATOS!$G$3:$G$5

Sheet REGISTRO
A3: REPORTE DIARIO DE TÉCNICOS
A4: FECHA | B4: TECNICO | C4: TURNO | D4: HR. INICIO | E4: HR. FIN | F4: T.Total | G4: MAQUINA/AREA/EQUIPO | H4: CLASIFICACIÓN | I4: TIPO ACTIVIDAD | J4: P/NP | K4: M/E | L4: DESCRIPCION DE TRABAJO | M4: ACTIVIDAD CORRECTIVO | N4: PIEZA | O4: PARTE | P4: PARTE 1 | Q4: PARTE 2 | R4: PARTE 3 | S4: DETALLE | T4: PIEZA - PARTE | U4: ACUM
A5: 45659 | B5: Carlos Puma | C5: TARDE | D5: 0.95833333 | E5: 0.16666667 | F5: =+MOD(Tabla8[[#This Row],[HR. FIN]]-Tabla8[[#This Row],[HR. INICIO]],1) -> 0.20833333 | G5: EMP. SACMI | H5: =IFERROR(VLOOKUP(G5,DATOS!$M$2:$N$219,2,FALSE),"") -> Maquinaria | I5: Trabajos menores | J5: =+VLOOKUP($I5,Tabla7[#All],2,FALSE) -> PROGRAMADA | K5: =IF(VLOOKUP(I5,Tabla7[#All],3,FALSE)=0,"",VLOOKUP(I5,Tabla7[#All],3,FALSE)) | L5: Apoyo a personal tercero retirando polin dañado para toma de medidas | N5: {=IFERROR(IF(Tabla8[[#This Row],[P/NP]]="NO PROGRAMADA","",_xlfn.TEXTJOIN(", ",TRUE,_xlfn._xlws.FILTER(Tabla4[[#All],[PIEZA]],ISNUMBER(SEARCH(Tabla4[[#All],[PCLAVE]],Tabla8[[#This Row],[DESCRIPCION DE TRABAJO]])),""))),"")} -> Polin De Arrastre | O5: {=_xlfn.TEXTJOIN(", ",TRUE,_xlfn._xlws.FILTER(Tabla28[[#All],[PARTE]],ISNUMBER(SEARCH(Tabla28[[#All],[PCLAVE2]],Tabla8[[#This Row],[DESCRIPCION DE TRABAJO]])),""))} | P5: =IFERROR(LEFT(O5, FIND(",", O5)-1), O5) | Q5: =IFERROR(IF(ISERROR(FIND(",", O5, FIND(",", O5)+1)), RIGHT(O5, LEN(O5)-FIND(",", O5)-1), MID(O5, FIND(",", O5)+2, FIND(",", O5, FIND(",", O5)+1)-FIND(",", O5)-2)), "") | R5: =IFERROR(RIGHT(O5, LEN(O5)-FIND(",", O5, FIND(",", O5)+1)-1), "") | S5: {=_xlfn.TEXTJOIN(", ",TRUE,_xlfn._xlws.FILTER(Tabla29[[#All],[PARTE]],ISNUMBER(SEARCH(Tabla29[[#All],[PCLAVE3]],Tabla8[[#This Row],[DESCRIPCION DE TRABAJO]])),""))} -> Dañado, Sustitucion | T5: =IF(AND(Tabla8[[#This Row],[PIEZA]]="",Tabla8[[#This Row],[PARTE]]=""),"VACIO","OK") -> OK | U5: =+CONCATENATE(WEEKNUM(Tabla8[[#This Row],[FECHA]]),"-",YEAR(Tabla8[[#This Row],[FECHA]])) -> 1-2025
A6: 45659 | B6: Carlos Puma | C6: TARDE | D6: 0.61111111 | E6: 0.71875 | F6: =+MOD(Tabla8[[#This Row],[HR. FIN]]-Tabla8[[#This Row],[HR. INICIO]],1) -> 0.10763889 | G6: HACOS 1 | H6: =IFERROR(VLOOKUP(G6,DATOS!$M$2:$N$219,2,FALSE),"") -> Maquinaria | I6: Sustitucion | J6: =+VLOOKUP($I6,Tabla7[#All],2,FALSE) -> NO PROGRAMADA | K6: =IF(VLOOKUP(I6,Tabla7[#All],3,FALSE)=0,"",VLOOKUP(I6,Tabla7[#All],3,FALSE)) -> ELÉCTRICA | L6: Error en C-14 | M6: Se hizo cambio de resorte de empujador de moldes, se reemplaza piston, se calibro sensores y se regulo el recorrido y velocidad de piston | N6: {=IFERROR(IF(Tabla8[[#This Row],[P/NP]]="NO PROGRAMADA","",_xlfn.TEXTJOIN(", ",TRUE,_xlfn._xlws.FILTER(Tabla4[[#All],[PIEZA]],ISNUMBER(SEARCH(Tabla4[[#All],[PCLAVE]],Tabla8[[#This Row],[DESCRIPCION DE TRABAJO]])),""))),"")} | O6: {=_xlfn.TEXTJOIN(", ",TRUE,_xlfn._xlws.FILTER(Tabla28[[#All],[PARTE]],ISNUMBER(SEARCH(Tabla28[[#All],[PCLAVE2]],Tabla8[[#This Row],[DESCRIPCION DE TRABAJO]])),""))} | P6: =IFERROR(LEFT(O6, FIND(",", O6)-1), O6) | Q6: =IFERROR(IF(ISERROR(FIND(",", O6, FIND(",", O6)+1)), RIGHT(O6, LEN(O6)-FIND(",", O6)-1), MID(O6, FIND(",", O6)+2, FIND(",", O6, FIND(",", O6)+1)-FIND(",", O6)-2)), "") | R6: =IFERROR(RIGHT(O6, LEN(O6)-FIND(",", O6, FIND(",", O6)+1)-1), "") | S6: {=_xlfn.TEXTJOIN(", ",TRUE,_xlfn._xlws.FILTER(Tabla29[[#All],[PARTE]],ISNUMBER(SEARCH(Tabla29[[#All],[PCLAVE3]],Tabla8[[#This Row],[DESCRIPCION DE TRABAJO]])),""))} -> Error | T6: =IF(AND(Tabla8[[#This Row],[PIEZA]]="",Tabla8[[#This Row],[PARTE]]=""),"VACIO","OK") -> VACIO | U6: =+CONCATENATE(WEEKNUM(Tabla8[[#This Row],[FECHA]]),"-",YEAR(Tabla8[[#This Row],[FECHA]])) -> 1-2025
A7: 45659 | B7: Carlos Puma | C7: TARDE | D7: 0.79861111 | E7: 0.84722222 | F7: =+MOD(Tabla8[[#This Row],[HR. FIN]]-Tabla8[[#This Row],[HR. INICIO]],1) -> 0.048611111 | G7: EMP. FLOWPACK 2 | H7: =IFERROR(VLOOKUP(G7,DATOS!$M$2:$N$219,2,FALSE),"") -> Maquinaria | I7: SET UP | J7: =+VLOOKUP($I7,Tabla7[#All],2,FALSE) -> PROGRAMADA | K7: =IF(VLOOKUP(I7,Tabla7[#All],3,FALSE)=0,"",VLOOKUP(I7,Tabla7[#All],3,FALSE)) | L7: Cambio de formato bitesize | M7: Se cambio cadena, empujadores y mordaza | N7: {=IFERROR(IF(Tabla8[[#This Row],[P/NP]]="NO PROGRAMADA","",_xlfn.TEXTJOIN(", ",TRUE,_xlfn._xlws.FILTER(Tabla4[[#All],[PIEZA]],ISNUMBER(SEARCH(Tabla4[[#All],[PCLAVE]],Tabla8[[#This Row],[DESCRIPCION DE TRABAJO]])),""))),"")} | O7: {=_xlfn.TEXTJOIN(", ",TRUE,_xlfn._xlws.FILTER(Tabla28[[#All],[PARTE]],ISNUMBER(SEARCH(Tabla28[[#All],[PCLAVE2]],Tabla8[[#This Row],[DESCRIPCION DE TRABAJO]])),""))} | P7: =IFERROR(LEFT(O7, FIND(",", O7)-1), O7) | Q7: =IFERROR(IF(ISERROR(FIND(",", O7, FIND(",", O7)+1)), RIGHT(O7, LEN(O7)-FIND(",", O7)-1), MID(O7, FIND(",", O7)+2, FIND(",", O7, FIND(",", O7)+1)-FIND(",", O7)-2)), "") | R7: =IFERROR(RIGHT(O7, LEN(O7)-FIND(",", O7, FIND(",", O7)+1)-1), "") | S7: {=_xlfn.TEXTJOIN(", ",TRUE,_xlfn._xlws.FILTER(Tabla29[[#All],[PARTE]],ISNUMBER(SEARCH(Tabla29[[#All],[PCLAVE3]],Tabla8[[#This Row],[DESCRIPCION DE TRABAJO]])),""))} -> Cambio De Formato | T7: =IF(AND(Tabla8[[#This Row],[PIEZA]]="",Tabla8[[#This Row],[PARTE]]=""),"VACIO","OK") -> VACIO | U7: =+CONCATENATE(WEEKNUM(Tabla8[[#This Row],[FECHA]]),"-",YEAR(Tabla8[[#This Row],[FECHA]])) -> 1-2025
A8: 45659 | B8: Cesar Quiroz | C8: MAÑANA | D8: 0.32291667 | E8: 0.36527778 | F8: =+MOD(Tabla8[[#This Row],[HR. FIN]]-Tabla8[[#This Row],[HR. INICIO]],1) -> 0.042361111 | G8: EMP. FLOWPACK 2 | H8: =IFERROR(VLOOKUP(G8,DATOS!$M$2:$N$219,2,FALSE),"") -> Maquinaria | I8: SET UP | J8: =+VLOOKUP($I8,Tabla7[#All],2,FALSE) -> PROGRAMADA | K8: =IF(VLOOKUP(I8,Tabla7[#All],3,FALSE)=0,"",VLOOKUP(I8,Tabla7[#All],3,FALSE)) | L8: Cambio de mordaza para minimilky | N8: {=IFERROR(IF(Tabla8[[#This Row],[P/NP]]="NO PROGRAMADA","",_xlfn.TEXTJOIN(", ",TRUE,_xlfn._xlws.FILTER(Tabla4[[#All],[PIEZA]],ISNUMBER(SEARCH(Tabla4[[#All],[PCLAVE]],Tabla8[[#This Row],[DESCRIPCION DE TRABAJO]])),""))),"")} -> Mordaza | O8: {=_xlfn.TEXTJOIN(", ",TRUE,_xlfn._xlws.FILTER(Tabla28[[#All],[PARTE]],ISNUMBER(SEARCH(Tabla28[[#All],[PCLAVE2]],Tabla8[[#This Row],[DESCRIPCION DE TRABAJO]])),""))} | P8: =IFERROR(LEFT(O8, FIND(",", O8)-1), O8) | Q8: =IFERROR(IF(ISERROR(FIND(",", O8, FIND(",", O8)+1)), RIGHT(O8, LEN(O8)-FIND(",", O8)-1), MID(O8, FIND(",", O8)+2, FIND(",", O8, FIND(",", O8)+1)-FIND(",", O8)-2)), "") | R8: =IFERROR(RIGHT(O8, LEN(O8)-FIND(",", O8, FIND(",", O8)+1)-1), "") | S8: {=_xlfn.TEXTJOIN(", ",TRUE,_xlfn._xlws.FILTER(Tabla29[[#All],[PARTE]],ISNUMBER(SEARCH(Tabla29[[#All],[PCLAVE3]],Tabla8[[#This Row],[DESCRIPCION DE TRABAJO]])),""))} | T8: =IF(AND(Tabla8[[#This Row],[PIEZA]]="",Tabla8[[#This Row],[PARTE]]=""),"VACIO","OK") -> OK | U8: =+CONCATENATE(WEEKNUM(Tabla8[[#This Row],[FECHA]]),"-",YEAR(Tabla8[[#This Row],[FECHA]])) -> 1-2025
A9: 45659 | B9: Omar Nina | C9: NOCHE | D9: 0.97222222 | E9: 1.0118056 | F9: =+MOD(Tabla8[[#This Row],[HR. FIN]]-Tabla8[[#This Row],[HR. INICIO]],1) -> 0.039583333 | G9: HACOS 1 | H9: =IFERROR(VLOOKUP(G9,DATOS!$M$2:$N$219,2,FALSE),"") -> Maquinaria | I9: SET UP | J9: =+VLOOKUP($I9,Tabla7[#All],2,FALSE) -> PROGRAMADA | K9: =IF(VLOOKUP(I9,Tabla7[#All],3,FALSE)=0,"",VLOOKUP(I9,Tabla7[#All],3,FALSE)) | L9: Cambio de formato a crema ovalada | M9: Se retiro plancha y usillo para lavar y se cambio cuchilla | N9: {=IFERROR(IF(Tabla8[[#This Row],[P/NP]]="NO PROGRAMADA","",_xlfn.TEXTJOIN(", ",TRUE,_xlfn._xlws.FILTER(Tabla4[[#All],[PIEZA]],ISNUMBER(SEARCH(Tabla4[[#All],[PCLAVE]],Tabla8[[#This Row],[DESCRIPCION DE TRABAJO]])),""))),"")} | O9: {=_xlfn.TEXTJOIN(", ",TRUE,_xlfn._xlws.FILTER(Tabla28[[#All],[PARTE]],ISNUMBER(SEARCH(Tabla28[[#All],[PCLAVE2]],Tabla8[[#This Row],[DESCRIPCION DE TRABAJO]])),""))} | P9: =IFERROR(LEFT(O9, FIND(",", O9)-1), O9) | Q9: =IFERROR(IF(ISERROR(FIND(",", O9, FIND(",", O9)+1)), RIGHT(O9, LEN(O9)-FIND(",", O9)-1), MID(O9, FIND(",", O9)+2, FIND(",", O9, FIND(",", O9)+1)-FIND(",", O9)-2)), "") | R9: =IFERROR(RIGHT(O9, LEN(O9)-FIND(",", O9, FIND(",", O9)+1)-1), "") | S9: {=_xlfn.TEXTJOIN(", ",TRUE,_xlfn._xlws.FILTER(Tabla29[[#All],[PARTE]],ISNUMBER(SEARCH(Tabla29[[#All],[PCLAVE3]],Tabla8[[#This Row],[DESCRIPCION DE TRABAJO]])),""))} -> Cambio De Formato | T9: =IF(AND(Tabla8[[#This Row],[PIEZA]]="",Tabla8[[#This Row],[PARTE]]=""),"VACIO","OK") -> VACIO | U9: =+CONCATENATE(WEEKNUM(Tabla8[[#This Row],[FECHA]]),"-",YEAR(Tabla8[[#This Row],[FECHA]])) -> 1-2025
A10: 45659 | B10: Cesar Quiroz | C10: MAÑANA | D10: 0.23333333 | E10: 0.26458333 | F10: =+MOD(Tabla8[[#This Row],[HR. FIN]]-Tabla8[[#This Row],[HR. INICIO]],1) -> 0.03125 | G10: MAQUINARIA DE PLANTA | H10: =IFERROR(VLOOKUP(G10,DATOS!$M$2:$N$219,2,FALSE),"") -> Maquinaria | I10: Encendido / Arranque de linea | J10: =+VLOOKUP($I10,Tabla7[#All],2,FALSE) -> PROGRAMADA | K10: =IF(VLOOKUP(I10,Tabla7[#All],3,FALSE)=0,"",VLOOKUP(I10,Tabla7[#All],3,FALSE)) | L10: Arranque de equipos de planta | N10: {=IFERROR(IF(Tabla8[[#This Row],[P/NP]]="NO PROGRAMADA","",_xlfn.TEXTJOIN(", ",TRUE,_xlfn._xlws.FILTER(Tabla4[[#All],[PIEZA]],ISNUMBER(SEARCH(Tabla4[[#All],[PCLAVE]],Tabla8[[#This Row],[DESCRIPCION DE TRABAJO]])),""))),"")} | O10: {=_xlfn.TEXTJOIN(", ",TRUE,_xlfn._xlws.FILTER(Tabla28[[#All],[PARTE]],ISNUMBER(SEARCH(Tabla28[[#All],[PCLAVE2]],Tabla8[[#This Row],[DESCRIPCION DE TRABAJO]])),""))} | P10: =IFERROR(LEFT(O10, FIND(",", O10)-1), O10) | Q10: =IFERROR(IF(ISERROR(FIND(",", O10, FIND(",", O10)+1)), RIGHT(O10, LEN(O10)-FIND(",", O10)-1), MID(O10, FIND(",", O10)+2, FIND(",", O10, FIND(",", O10)+1)-FIND(",", O10)-2)), "") | R10: =IFERROR(RIGHT(O10, LEN(O10)-FIND(",", O10, FIND(",", O10)+1)-1), "") | S10: {=_xlfn.TEXTJOIN(", ",TRUE,_xlfn._xlws.FILTER(Tabla29[[#All],[PARTE]],ISNUMBER(SEARCH(Tabla29[[#All],[PCLAVE3]],Tabla8[[#This Row],[DESCRIPCION DE TRABAJO]])),""))} | T10: =IF(AND(Tabla8[[#This Row],[PIEZA]]="",Tabla8[[#This Row],[PARTE]]=""),"VACIO","OK") -> VACIO | U10: =+CONCATENATE(WEEKNUM(Tabla8[[#This Row],[FECHA]]),"-",YEAR(Tabla8[[#This Row],[FECHA]])) -> 1-2025
A11: 45659 | B11: Cesar Quiroz | C11: MAÑANA | D11: 0.29861111 | E11: 0.32083333 | F11: =+MOD(Tabla8[[#This Row],[HR. FIN]]-Tabla8[[#This Row],[HR. INICIO]],1) -> 0.022222222 | G11: HACOS 1 | H11: =IFERROR(VLOOKUP(G11,DATOS!$M$2:$N$219,2,FALSE),"") -> Maquinaria | I11: SET UP | J11: =+VLOOKUP($I11,Tabla7[#All],2,FALSE) -> PROGRAMADA | K11: =IF(VLOOKUP(I11,Tabla7[#All],3,FALSE)=0,"",VLOOKUP(I11,Tabla7[#All],3,FALSE)) | L11: Armado de formato x50 agregados en MDS | N11: {=IFERROR(IF(Tabla8[[#This Row],[P/NP]]="NO PROGRAMADA","",_xlfn.TEXTJOIN(", ",TRUE,_xlfn._xlws.FILTER(Tabla4[[#All],[PIEZA]],ISNUMBER(SEARCH(Tabla4[[#All],[PCLAVE]],Tabla8[[#This Row],[DESCRIPCION DE TRABAJO]])),""))),"")} | O11: {=_xlfn.TEXTJOIN(", ",TRUE,_xlfn._xlws.FILTER(Tabla28[[#All],[PARTE]],ISNUMBER(SEARCH(Tabla28[[#All],[PCLAVE2]],Tabla8[[#This Row],[DESCRIPCION DE TRABAJO]])),""))} -> Mds | P11: =IFERROR(LEFT(O11, FIND(",", O11)-1), O11) -> Mds | Q11: =IFERROR(IF(ISERROR(FIND(",", O11, FIND(",", O11)+1)), RIGHT(O11, LEN(O11)-FIND(",", O11)-1), MID(O11, FIND(",", O11)+2, FIND(",", O11, FIND(",", O11)+1)-FIND(",", O11)-2)), "") | R11: =IFERROR(RIGHT(O11, LEN(O11)-FIND(",", O11, FIND(",", O11)+1)-1), "") | S11: {=_xlfn.TEXTJOIN(", ",TRUE,_xlfn._xlws.FILTER(Tabla29[[#All],[PARTE]],ISNUMBER(SEARCH(Tabla29[[#All],[PCLAVE3]],Tabla8[[#This Row],[DESCRIPCION DE TRABAJO]])),""))} -> Cambio De Formato | T11: =IF(AND(Tabla8[[#This Row],[PIEZA]]="",Tabla8[[#This Row],[PARTE]]=""),"VACIO","OK") -> OK | U11: =+CONCATENATE(WEEKNUM(Tabla8[[#This Row],[FECHA]]),"-",YEAR(Tabla8[[#This Row],[FECHA]])) -> 1-2025
A12: 45659 | B12: Cesar Quiroz | C12: MAÑANA | D12: 0.50694444 | E12: 0.52638889 | F12: =+MOD(Tabla8[[#This Row],[HR. FIN]]-Tabla8[[#This Row],[HR. INICIO]],1) -> 0.019444444 | G12: HACOS 1 | H12: =IFERROR(VLOOKUP(G12,DATOS!$M$2:$N$219,2,FALSE),"") -> Maquinaria | I12: SET UP | J12: =+VLOOKUP($I12,Tabla7[#All],2,FALSE) -> PROGRAMADA | K12: =IF(VLOOKUP(I12,Tabla7[#All],3,FALSE)=0,"",VLOOKUP(I12,Tabla7[#All],3,FALSE)) | L12: Armado de formato cremas en MDS | N12: {=IFERROR(IF(Tabla8[[#This Row],[P/NP]]="NO PROGRAMADA","",_xlfn.TEXTJOIN(", ",TRUE,_xlfn._xlws.FILTER(Tabla4[[#All],[PIEZA]],ISNUMBER(SEARCH(Tabla4[[#All],[PCLAVE]],Tabla8[[#This Row],[DESCRIPCION DE TRABAJO]])),""))),"")} | O12: {=_xlfn.TEXTJOIN(", ",TRUE,_xlfn._xlws.FILTER(Tabla28[[#All],[PARTE]],ISNUMBER(SEARCH(Tabla28[[#All],[PCLAVE2]],Tabla8[[#This Row],[DESCRIPCION DE TRABAJO]])),""))} -> Mds | P12: =IFERROR(LEFT(O12, FIND(",", O12)-1), O12) -> Mds | Q12: =IFERROR(IF(ISERROR(FIND(",", O12, FIND(",", O12)+1)), RIGHT(O12, LEN(O12)-FIND(",", O12)-1), MID(O12, FIND(",", O12)+2, FIND(",", O12, FIND(",", O12)+1)-FIND(",", O12)-2)), "") | R12: =IFERROR(RIGHT(O12, LEN(O12)-FIND(",", O12, FIND(",", O12)+1)-1), "") | S12: {=_xlfn.TEXTJOIN(", ",TRUE,_xlfn._xlws.FILTER(Tabla29[[#All],[PARTE]],ISNUMBER(SEARCH(Tabla29[[#All],[PCLAVE3]],Tabla8[[#This Row],[DESCRIPCION DE TRABAJO]])),""))} -> Cambio De Formato | T12: =IF(AND(Tabla8[[#This Row],[PIEZA]]="",Tabla8[[#This Row],[PARTE]]=""),"VACIO","OK") -> OK | U12: =+CONCATENATE(WEEKNUM(Tabla8[[#This Row],[FECHA]]),"-",YEAR(Tabla8[[#This Row],[FECHA]])) -> 1-2025
A13: 45659 | B13: Cesar Quiroz | C13: MAÑANA | D13: 0.48541667 | E13: 0.50486111 | F13: =+MOD(Tabla8[[#This Row],[HR. FIN]]-Tabla8[[#This Row],[HR. INICIO]],1) -> 0.019444444 | G13: HACOS 1 | H13: =IFERROR(VLOOKUP(G13,DATOS!$M$2:$N$219,2,FALSE),"") -> Maquinaria | I13: SET UP | J13: =+VLOOKUP($I13,Tabla7[#All],2,FALSE) -> PROGRAMADA | K13: =IF(VLOOKUP(I13,Tabla7[#All],3,FALSE)=0,"",VLOOKUP(I13,Tabla7[#All],3,FALSE)) | L13: Desarmado de formato agregados x50 MDS | N13: {=IFERROR(IF(Tabla8[[#This Row],[P/NP]]="NO PROGRAMADA","",_xlfn.TEXTJOIN(", ",TRUE,_xlfn._xlws.FILTER(Tabla4[[#All],[PIEZA]],ISNUMBER(SEARCH(Tabla4[[#All],[PCLAVE]],Tabla8[[#This Row],[DESCRIPCION DE TRABAJO]])),""))),"")} | O13: {=_xlfn.TEXTJOIN(", ",TRUE,_xlfn._xlws.FILTER(Tabla28[[#All],[PARTE]],ISNUMBER(SEARCH(Tabla28[[#All],[PCLAVE2]],Tabla8[[#This Row],[DESCRIPCION DE TRABAJO]])),""))} -> Mds | P13: =IFERROR(LEFT(O13, FIND(",", O13)-1), O13) -> Mds | Q13: =IFERROR(IF(ISERROR(FIND(",", O13, FIND(",", O13)+1)), RIGHT(O13, LEN(O13)-FIND(",", O13)-1), MID(O13, FIND(",", O13)+2, FIND(",", O13, FIND(",", O13)+1)-FIND(",", O13)-2)), "") | R13: =IFERROR(RIGHT(O13, LEN(O13)-FIND(",", O13, FIND(",", O13)+1)-1), "") | S13: {=_xlfn.TEXTJOIN(", ",TRUE,_xlfn._xlws.FILTER(Tabla29[[#All],[PARTE]],ISNUMBER(SEARCH(Tabla29[[#All],[PCLAVE3]],Tabla8[[#This Row],[DESCRIPCION DE TRABAJO]])),""))} -> Cambio De Formato | T13: =IF(AND(Tabla8[[#This Row],[PIEZA]]="",Tabla8[[#This Row],[PARTE]]=""),"VACIO","OK") -> OK | U13: =+CONCATENATE(WEEKNUM(Tabla8[[#This Row],[FECHA]]),"-",YEAR(Tabla8[[#This Row],[FECHA]])) -> 1-2025
A14: 45659 | B14: Cesar Quiroz | C14: MAÑANA | D14: 0.27569444 | E14: 0.29444444 | F14: =+MOD(Tabla8[[#This Row],[HR. FIN]]-Tabla8[[#This Row],[HR. INICIO]],1) -> 0.01875 | G14: HACOS 1 | H14: =IFERROR(VLOOKUP(G14,DATOS!$M$2:$N$219,2,FALSE),"") -> Maquinaria | I14: SET UP | J14: =+VLOOKUP($I14,Tabla7[#All],2,FALSE) -> PROGRAMADA | K14: =IF(VLOOKUP(I14,Tabla7[#All],3,FALSE)=0,"",VLOOKUP(I14,Tabla7[#All],3,FALSE)) | L14: Desarmado de formato x100 agregados en MDS | N14: {=IFERROR(IF(Tabla8[[#This Row],[P/NP]]="NO PROGRAMADA","",_xlfn.TEXTJOIN(", ",TRUE,_xlfn._xlws.FILTER(Tabla4[[#All],[PIEZA]],ISNUMBER(SEARCH(Tabla4[[#All],[PCLAVE]],Tabla8[[#This Row],[DESCRIPCION DE TRABAJO]])),""))),"")} | O14: {=_xlfn.TEXTJOIN(", ",TRUE,_xlfn._xlws.FILTER(Tabla28[[#All],[PARTE]],ISNUMBER(SEARCH(Tabla28[[#All],[PCLAVE2]],Tabla8[[#This Row],[DESCRIPCION DE TRABAJO]])),""))} -> Mds | P14: =IFERROR(LEFT(O14, FIND(",", O14)-1), O14) -> Mds | Q14: =IFERROR(IF(ISERROR(FIND(",", O14, FIND(",", O14)+1)), RIGHT(O14, LEN(O14)-FIND(",", O14)-1), MID(O14, FIND(",", O14)+2, FIND(",", O14, FIND(",", O14)+1)-FIND(",", O14)-2)), "") | R14: =IFERROR(RIGHT(O14, LEN(O14)-FIND(",", O14, FIND(",", O14)+1)-1), "") | S14: {=_xlfn.TEXTJOIN(", ",TRUE,_xlfn._xlws.FILTER(Tabla29[[#All],[PARTE]],ISNUMBER(SEARCH(Tabla29[[#All],[PCLAVE3]],Tabla8[[#This Row],[DESCRIPCION DE TRABAJO]])),""))} -> Cambio De Formato | T14: =IF(AND(Tabla8[[#This Row],[PIEZA]]="",Tabla8[[#This Row],[PARTE]]=""),"VACIO","OK") -> OK | U14: =+CONCATENATE(WEEKNUM(Tabla8[[#This Row],[FECHA]]),"-",YEAR(Tabla8[[#This Row],[FECHA]])) -> 1-2025
A15: 45659 | B15: Omar Nina | C15: NOCHE | D15: 0.14861111 | E15: 0.16666667 | F15: =+MOD(Tabla8[[#This Row],[HR. FIN]]-Tabla8[[#This Row],[HR. INICIO]],1) -> 0.018055556 | G15: 5TO PISO | H15: =IFERROR(VLOOKUP(G15,DATOS!$M$2:$N$219,2,FALSE),"") -> Area | I15: Trabajos menores | J15: =+VLOOKUP($I15,Tabla7[#All],2,FALSE) -> PROGRAMADA | K15: =IF(VLOOKUP(I15,Tabla7[#All],3,FALSE)=0,"",VLOOKUP(I15,Tabla7[#All],3,FALSE)) | L15: Apoyo a calidad colocando dispensado de papel | N15: {=IFERROR(IF(Tabla8[[#This Row],[P/NP]]="NO PROGRAMADA","",_xlfn.TEXTJOIN(", ",TRUE,_xlfn._xlws.FILTER(Tabla4[[#All],[PIEZA]],ISNUMBER(SEARCH(Tabla4[[#All],[PCLAVE]],Tabla8[[#This Row],[DESCRIPCION DE TRABAJO]])),""))),"")} -> Dispensador | O15: {=_xlfn.TEXTJOIN(", ",TRUE,_xlfn._xlws.FILTER(Tabla28[[#All],[PARTE]],ISNUMBER(SEARCH(Tabla28[[#All],[PCLAVE2]],Tabla8[[#This Row],[DESCRIPCION DE TRABAJO]])),""))} | P15: =IFERROR(LEFT(O15, FIND(",", O15)-1), O15) | Q15: =IFERROR(IF(ISERROR(FIND(",", O15, FIND(",", O15)+1)), RIGHT(O15, LEN(O15)-FIND(",", O15)-1), MID(O15, FIND(",", O15)+2, FIND(",", O15, FIND(",", O15)+1)-FIND(",", O15)-2)), "") | R15: =IFERROR(RIGHT(O15, LEN(O15)-FIND(",", O15, FIND(",", O15)+1)-1), "") | S15: {=_xlfn.TEXTJOIN(", ",TRUE,_xlfn._xlws.FILTER(Tabla29[[#All],[PARTE]],ISNUMBER(SEARCH(Tabla29[[#All],[PCLAVE3]],Tabla8[[#This Row],[DESCRIPCION DE TRABAJO]])),""))} | T15: =IF(AND(Tabla8[[#This Row],[PIEZA]]="",Tabla8[[#This Row],[PARTE]]=""),"VACIO","OK") -> OK | U15: =+CONCATENATE(WEEKNUM(Tabla8[[#This Row],[FECHA]]),"-",YEAR(Tabla8[[#This Row],[FECHA]])) -> 1-2025
A16: 45659 | B16: Omar Nina | C16: NOCHE | D16: 0.90972222 | E16: 0.92708333 | F16: =+MOD(Tabla8[[#This Row],[HR. FIN]]-Tabla8[[#This Row],[HR. INICIO]],1) -> 0.017361111 | G16: EMP. FLOWPACK 2 | H16: =IFERROR(VLOOKUP(G16,DATOS!$M$2:$N$219,2,FALSE),"") -> Maquinaria | I16: SET UP | J16: =+VLOOKUP($I16,Tabla7[#All],2,FALSE) -> PROGRAMADA | K16: =IF(VLOOKUP(I16,Tabla7[#All],3,FALSE)=0,"",VLOOKUP(I16,Tabla7[#All],3,FALSE)) | L16: Programa no responde | M16: Se reinicia ambos tableros y se probo. Queda operativo | N16: {=IFERROR(IF(Tabla8[[#This Row],[P/NP]]="NO PROGRAMADA","",_xlfn.TEXTJOIN(", ",TRUE,_xlfn._xlws.FILTER(Tabla4[[#All],[PIEZA]],ISNUMBER(SEARCH(Tabla4[[#All],[PCLAVE]],Tabla8[[#This Row],[DESCRIPCION DE TRABAJO]])),""))),"")} | O16: {=_xlfn.TEXTJOIN(", ",TRUE,_xlfn._xlws.FILTER(Tabla28[[#All],[PARTE]],ISNUMBER(SEARCH(Tabla28[[#All],[PCLAVE2]],Tabla8[[#This Row],[DESCRIPCION DE TRABAJO]])),""))} | P16: =IFERROR(LEFT(O16, FIND(",", O16)-1), O16) | Q16: =IFERROR(IF(ISERROR(FIND(",", O16, FIND(",", O16)+1)), RIGHT(O16, LEN(O16)-FIND(",", O16)-1), MID(O16, FIND(",", O16)+2, FIND(",", O16, FIND(",", O16)+1)-FIND(",", O16)-2)), "") | R16: =IFERROR(RIGHT(O16, LEN(O16)-FIND(",", O16, FIND(",", O16)+1)-1), "") | S16: {=_xlfn.TEXTJOIN(", ",TRUE,_xlfn._xlws.FILTER(Tabla29[[#All],[PARTE]],ISNUMBER(SEARCH(Tabla29[[#All],[PCLAVE3]],Tabla8[[#This Row],[DESCRIPCION DE TRABAJO]])),""))} -> No Responde | T16: =IF(AND(Tabla8[[#This Row],[PIEZA]]="",Tabla8[[#This Row],[PARTE]]=""),"VACIO","OK") -> VACIO | U16: =+CONCATENATE(WEEKNUM(Tabla8[[#This Row],[FECHA]]),"-",YEAR(Tabla8[[#This Row],[FECHA]])) -> 1-2025
A17: 45659 | B17: Omar Nina | C17: NOCHE | D17: 0.083333333 | E17: 0.10069444 | F17: =+MOD(Tabla8[[#This Row],[HR. FIN]]-Tabla8[[#This Row],[HR. INICIO]],1) -> 0.017361111 | G17: 5TO PISO | H17: =IFERROR(VLOOKUP(G17,DATOS!$M$2:$N$219,2,FALSE),"") -> Area | I17: Trabajos menores | J17: =+VLOOKUP($I17,Tabla7[#All],2,FALSE) -> PROGRAMADA | K17: =IF(VLOOKUP(I17,Tabla7[#All],3,FALSE)=0,"",VLOOKUP(I17,Tabla7[#All],3,FALSE)) | L17: Se apoya a calidad colocando dispensador | N17: {=IFERROR(IF(Tabla8[[#This Row],[P/NP]]="NO PROGRAMADA","",_xlfn.TEXTJOIN(", ",TRUE,_xlfn._xlws.FILTER(Tabla4[[#All],[PIEZA]],ISNUMBER(SEARCH(Tabla4[[#All],[PCLAVE]],Tabla8[[#This Row],[DESCRIPCION DE TRABAJO]])),""))),"")} -> Dispensador | O17: {=_xlfn.TEXTJOIN(", ",TRUE,_xlfn._xlws.FILTER(Tabla28[[#All],[PARTE]],ISNUMBER(SEARCH(Tabla28[[#All],[PCLAVE2]],Tabla8[[#This Row],[DESCRIPCION DE TRABAJO]])),""))} | P17: =IFERROR(LEFT(O17, FIND(",", O17)-1), O17) | Q17: =IFERROR(IF(ISERROR(FIND(",", O17, FIND(",", O17)+1)), RIGHT(O17, LEN(O17)-FIND(",", O17)-1), MID(O17, FIND(",", O17)+2, FIND(",", O17, FIND(",", O17)+1)-FIND(",", O17)-2)), "") | R17: =IFERROR(RIGHT(O17, LEN(O17)-FIND(",", O17, FIND(",", O17)+1)-1), "") | S17: {=_xlfn.TEXTJOIN(", ",TRUE,_xlfn._xlws.FILTER(Tabla29[[#All],[PARTE]],ISNUMBER(SEARCH(Tabla29[[#All],[PCLAVE3]],Tabla8[[#This Row],[DESCRIPCION DE TRABAJO]])),""))} | T17: =IF(AND(Tabla8[[#This Row],[PIEZA]]="",Tabla8[[#This Row],[PARTE]]=""),"VACIO","OK") -> OK | U17: =+CONCATENATE(WEEKNUM(Tabla8[[#This Row],[FECHA]]),"-",YEAR(Tabla8[[#This Row],[FECHA]])) -> 1-2025
A18: 45659 | B18: Omar Nina | C18: NOCHE | D18: 0.17708333 | E18: 0.19444444 | F18: =+MOD(Tabla8[[#This Row],[HR. FIN]]-Tabla8[[#This Row],[HR. INICIO]],1) -> 0.017361111 | G18: EMP. FLOWPACK 2 | H18: =IFERROR(VLOOKUP(G18,DATOS!$M$2:$N$219,2,FALSE),"") -> Maquinaria | I18: Inspección | J18: =+VLOOKUP($I18,Tabla7[#All],2,FALSE) -> PROGRAMADA | K18: =IF(VLOOKUP(I18,Tabla7[#All],3,FALSE)=0,"",VLOOKUP(I18,Tabla7[#All],3,FALSE)) | L18: Inspeccion de equipo | N18: {=IFERROR(IF(Tabla8[[#This Row],[P/NP]]="NO PROGRAMADA","",_xlfn.TEXTJOIN(", ",TRUE,_xlfn._xlws.FILTER(Tabla4[[#All],[PIEZA]],ISNUMBER(SEARCH(Tabla4[[#All],[PCLAVE]],Tabla8[[#This Row],[DESCRIPCION DE TRABAJO]])),""))),"")} | O18: {=_xlfn.TEXTJOIN(", ",TRUE,_xlfn._xlws.FILTER(Tabla28[[#All],[PARTE]],ISNUMBER(SEARCH(Tabla28[[#All],[PCLAVE2]],Tabla8[[#This Row],[DESCRIPCION DE TRABAJO]])),""))} | P18: =IFERROR(LEFT(O18, FIND(",", O18)-1), O18) | Q18: =IFERROR(IF(ISERROR(FIND(",", O18, FIND(",", O18)+1)), RIGHT(O18, LEN(O18)-FIND(",", O18)-1), MID(O18, FIND(",", O18)+2, FIND(",", O18, FIND(",", O18)+1)-FIND(",", O18)-2)), "") | R18: =IFERROR(RIGHT(O18, LEN(O18)-FIND(",", O18, FIND(",", O18)+1)-1), "") | S18: {=_xlfn.TEXTJOIN(", ",TRUE,_xlfn._xlws.FILTER(Tabla29[[#All],[PARTE]],ISNUMBER(SEARCH(Tabla29[[#All],[PCLAVE3]],Tabla8[[#This Row],[DESCRIPCION DE TRABAJO]])),""))} | T18: =IF(AND(Tabla8[[#This Row],[PIEZA]]="",Tabla8[[#This Row],[PARTE]]=""),"VACIO","OK") -> VACIO | U18: =+CONCATENATE(WEEKNUM(Tabla8[[#This Row],[FECHA]]),"-",YEAR(Tabla8[[#This Row],[FECHA]])) -> 1-2025
A19: 45659 | B19: Carlos Puma | C19: TARDE | D19: 0.55902778 | E19: 0.57638889 | F19: =+MOD(Tabla8[[#This Row],[HR. FIN]]-Tabla8[[#This Row],[HR. INICIO]],1) -> 0.017361111 | G19: FORRADORA AUTOMATICA | H19: =IFERROR(VLOOKUP(G19,DATOS!$M$2:$N$219,2,FALSE),"") -> Maquinaria | I19: Ajuste /Calibracion | J19: =+VLOOKUP($I19,Tabla7[#All],2,FALSE) -> NO PROGRAMADA | K19: =IF(VLOOKUP(I19,Tabla7[#All],3,FALSE)=0,"",VLOOKUP(I19,Tabla7[#All],3,FALSE)) -> MECÁNICA | L19: Faja detenida | M19: Se alineo faja y se dio seguimiento | N19: {=IFERROR(IF(Tabla8[[#This Row],[P/NP]]="NO PROGRAMADA","",_xlfn.TEXTJOIN(", ",TRUE,_xlfn._xlws.FILTER(Tabla4[[#All],[PIEZA]],ISNUMBER(SEARCH(Tabla4[[#All],[PCLAVE]],Tabla8[[#This Row],[DESCRIPCION DE TRABAJO]])),""))),"")} | O19: {=_xlfn.TEXTJOIN(", ",TRUE,_xlfn._xlws.FILTER(Tabla28[[#All],[PARTE]],ISNUMBER(SEARCH(Tabla28[[#All],[PCLAVE2]],Tabla8[[#This Row],[DESCRIPCION DE TRABAJO]])),""))} | P19: =IFERROR(LEFT(O19, FIND(",", O19)-1), O19) | Q19: =IFERROR(IF(ISERROR(FIND(",", O19, FIND(",", O19)+1)), RIGHT(O19, LEN(O19)-FIND(",", O19)-1), MID(O19, FIND(",", O19)+2, FIND(",", O19, FIND(",", O19)+1)-FIND(",", O19)-2)), "") | R19: =IFERROR(RIGHT(O19, LEN(O19)-FIND(",", O19, FIND(",", O19)+1)-1), "") | S19: {=_xlfn.TEXTJOIN(", ",TRUE,_xlfn._xlws.FILTER(Tabla29[[#All],[PARTE]],ISNUMBER(SEARCH(Tabla29[[#All],[PCLAVE3]],Tabla8[[#This Row],[DESCRIPCION DE TRABAJO]])),""))} -> Detenido, Detenido | T19: =IF(AND(Tabla8[[#This Row],[PIEZA]]="",Tabla8[[#This Row],[PARTE]]=""),"VACIO","OK") -> VACIO | U19: =+CONCATENATE(WEEKNUM(Tabla8[[#This Row],[FECHA]]),"-",YEAR(Tabla8[[#This Row],[FECHA]])) -> 1-2025
A20: 45659 | B20: Carlos Puma | C20: TARDE | D20: 0.72222222 | E20: 0.73611111 | F20: =+MOD(Tabla8[[#This Row],[HR. FIN]]-Tabla8[[#This Row],[HR. INICIO]],1) -> 0.013888889 | G20: NETCH | H20: =IFERROR(VLOOKUP(G20,DATOS!$M$2:$N$219,2,FALSE),"") -> Maquinaria | I20: Limpieza | J20: =+VLOOKUP($I20,Tabla7[#All],2,FALSE) -> PROGRAMADA | K20: =IF(VLOOKUP(I20,Tabla7[#All],3,FALSE)=0,"",VLOOKUP(I20,Tabla7[#All],3,FALSE)) | L20: Se desarma equipo para limpieza | N20: {=IFERROR(IF(Tabla8[[#This Row],[P/NP]]="NO PROGRAMADA","",_xlfn.TEXTJOIN(", ",TRUE,_xlfn._xlws.FILTER(Tabla4[[#All],[PIEZA]],ISNUMBER(SEARCH(Tabla4[[#All],[PCLAVE]],Tabla8[[#This Row],[DESCRIPCION DE TRABAJO]])),""))),"")} | O20: {=_xlfn.TEXTJOIN(", ",TRUE,_xlfn._xlws.FILTER(Tabla28[[#All],[PARTE]],ISNUMBER(SEARCH(Tabla28[[#All],[PCLAVE2]],Tabla8[[#This Row],[DESCRIPCION DE TRABAJO]])),""))} | P20: =IFERROR(LEFT(O20, FIND(",", O20)-1), O20) | Q20: =IFERROR(IF(ISERROR(FIND(",", O20, FIND(",", O20)+1)), RIGHT(O20, LEN(O20)-FIND(",", O20)-1), MID(O20, FIND(",", O20)+2, FIND(",", O20, FIND(",", O20)+1)-FIND(",", O20)-2)), "") | R20: =IFERROR(RIGHT(O20, LEN(O20)-FIND(",", O20, FIND(",", O20)+1)-1), "") | S20: {=_xlfn.TEXTJOIN(", ",TRUE,_xlfn._xlws.FILTER(Tabla29[[#All],[PARTE]],ISNUMBER(SEARCH(Tabla29[[#All],[PCLAVE3]],Tabla8[[#This Row],[DESCRIPCION DE TRABAJO]])),""))} | T20: =IF(AND(Tabla8[[#This Row],[PIEZA]]="",Tabla8[[#This Row],[PARTE]]=""),"VACIO","OK") -> VACIO | U20: =+CONCATENATE(WEEKNUM(Tabla8[[#This Row],[FECHA]]),"-",YEAR(Tabla8[[#This Row],[FECHA]])) -> 1-2025
A21: 45659 | B21: Omar Nina | C21: NOCHE | D21: 0.055555556 | E21: 0.069444444 | F21: =+MOD(Tabla8[[#This Row],[HR. FIN]]-Tabla8[[#This Row],[HR. INICIO]],1) -> 0.013888889 | G21: HACOS 1 | H21: =IFERROR(VLOOKUP(G21,DATOS!$M$2:$N$219,2,FALSE),"") -> Maquinaria | I21: Inspección | J21: =+VLOOKUP($I21,Tabla7[#All],2,FALSE) -> PROGRAMADA | K21: =IF(VLOOKUP(I21,Tabla7[#All],3,FALSE)=0,"",VLOOKUP(I21,Tabla7[#All],3,FALSE)) | L21: Inspeccion de funcionamiento de maquinas | N21: {=IFERROR(IF(Tabla8[[#This Row],[P/NP]]="NO PROGRAMADA","",_xlfn.TEXTJOIN(", ",TRUE,_xlfn._xlws.FILTER(Tabla4[[#All],[PIEZA]],ISNUMBER(SEARCH(Tabla4[[#All],[PCLAVE]],Tabla8[[#This Row],[DESCRIPCION DE TRABAJO]])),""))),"")} | O21: {=_xlfn.TEXTJOIN(", ",TRUE,_xlfn._xlws.FILTER(Tabla28[[#All],[PARTE]],ISNUMBER(SEARCH(Tabla28[[#All],[PCLAVE2]],Tabla8[[#This Row],[DESCRIPCION DE TRABAJO]])),""))} | P21: =IFERROR(LEFT(O21, FIND(",", O21)-1), O21) | Q21: =IFERROR(IF(ISERROR(FIND(",", O21, FIND(",", O21)+1)), RIGHT(O21, LEN(O21)-FIND(",", O21)-1), MID(O21, FIND(",", O21)+2, FIND(",", O21, FIND(",", O21)+1)-FIND(",", O21)-2)), "") | R21: =IFERROR(RIGHT(O21, LEN(O21)-FIND(",", O21, FIND(",", O21)+1)-1), "") | S21: {=_xlfn.TEXTJOIN(", ",TRUE,_xlfn._xlws.FILTER(Tabla29[[#All],[PARTE]],ISNUMBER(SEARCH(Tabla29[[#All],[PCLAVE3]],Tabla8[[#This Row],[DESCRIPCION DE TRABAJO]])),""))} | T21: =IF(AND(Tabla8[[#This Row],[PIEZA]]="",Tabla8[[#This Row],[PARTE]]=""),"VACIO","OK") -> VACIO | U21: =+CONCATENATE(WEEKNUM(Tabla8[[#This Row],[FECHA]]),"-",YEAR(Tabla8[[#This Row],[FECHA]])) -> 1-2025
A22: 45659 | B22: Omar Nina | C22: NOCHE | D22: 0.9375 | E22: 0.95138889 | F22: =+MOD(Tabla8[[#This Row],[HR. FIN]]-Tabla8[[#This Row],[HR. INICIO]],1) -> 0.013888889 | G22: HANSEL | H22: =IFERROR(VLOOKUP(G22,DATOS!$M$2:$N$219,2,FALSE),"") -> Maquinaria | I22: Inspección | J22: =+VLOOKUP($I22,Tabla7[#All],2,FALSE) -> PROGRAMADA | K22: =IF(VLOOKUP(I22,Tabla7[#All],3,FALSE)=0,"",VLOOKUP(I22,Tabla7[#All],3,FALSE)) | L22: Inspeccion de equipo | N22: {=IFERROR(IF(Tabla8[[#This Row],[P/NP]]="NO PROGRAMADA","",_xlfn.TEXTJOIN(", ",TRUE,_xlfn._xlws.FILTER(Tabla4[[#All],[PIEZA]],ISNUMBER(SEARCH(Tabla4[[#All],[PCLAVE]],Tabla8[[#This Row],[DESCRIPCION DE TRABAJO]])),""))),"")} | O22: {=_xlfn.TEXTJOIN(", ",TRUE,_xlfn._xlws.FILTER(Tabla28[[#All],[PARTE]],ISNUMBER(SEARCH(Tabla28[[#All],[PCLAVE2]],Tabla8[[#This Row],[DESCRIPCION DE TRABAJO]])),""))} | P22: =IFERROR(LEFT(O22, FIND(",", O22)-1), O22) | Q22: =IFERROR(IF(ISERROR(FIND(",", O22, FIND(",", O22)+1)), RIGHT(O22, LEN(O22)-FIND(",", O22)-1), MID(O22, FIND(",", O22)+2, FIND(",", O22, FIND(",", O22)+1)-FIND(",", O22)-2)), "") | R22: =IFERROR(RIGHT(O22, LEN(O22)-FIND(",", O22, FIND(",", O22)+1)-1), "") | S22: {=_xlfn.TEXTJOIN(", ",TRUE,_xlfn._xlws.FILTER(Tabla29[[#All],[PARTE]],ISNUMBER(SEARCH(Tabla29[[#All],[PCLAVE3]],Tabla8[[#This Row],[DESCRIPCION DE TRABAJO]])),""))} | T22: =IF(AND(Tabla8[[#This Row],[PIEZA]]="",Tabla8[[#This Row],[PARTE]]=""),"VACIO","OK") -> VACIO | U22: =+CONCATENATE(WEEKNUM(Tabla8[[#This Row],[FECHA]]),"-",YEAR(Tabla8[[#This Row],[FECHA]])) -> 1-2025
A23: 45659 | B23: Cesar Quiroz | C23: MAÑANA | D23: 0.37777778 | E23: 0.39097222 | F23: =+MOD(Tabla8[[#This Row],[HR. FIN]]-Tabla8[[#This Row],[HR. INICIO]],1) -> 0.013194444 | G23: EMP. FLOWPACK 2 | H23: =IFERROR(VLOOKUP(G23,DATOS!$M$2:$N$219,2,FALSE),"") -> Maquinaria | I23: Ajuste /Calibracion | J23: =+VLOOKUP($I23,Tabla7[#All],2,FALSE) -> NO PROGRAMADA | K23: =IF(VLOOKUP(I23,Tabla7[#All],3,FALSE)=0,"",VLOOKUP(I23,Tabla7[#All],3,FALSE)) -> MECÁNICA | L23: Laminado se mueve nose puede calibrar | M23: Se apoyo en la alineacion de laminado. Se realizo pruebas | N23: {=IFERROR(IF(Tabla8[[#This Row],[P/NP]]="NO PROGRAMADA","",_xlfn.TEXTJOIN(", ",TRUE,_xlfn._xlws.FILTER(Tabla4[[#All],[PIEZA]],ISNUMBER(SEARCH(Tabla4[[#All],[PCLAVE]],Tabla8[[#This Row],[DESCRIPCION DE TRABAJO]])),""))),"")} | O23: {=_xlfn.TEXTJOIN(", ",TRUE,_xlfn._xlws.FILTER(Tabla28[[#All],[PARTE]],ISNUMBER(SEARCH(Tabla28[[#All],[PCLAVE2]],Tabla8[[#This Row],[DESCRIPCION DE TRABAJO]])),""))} | P23: =IFERROR(LEFT(O23, FIND(",", O23)-1), O23) | Q23: =IFERROR(IF(ISERROR(FIND(",", O23, FIND(",", O23)+1)), RIGHT(O23, LEN(O23)-FIND(",", O23)-1), MID(O23, FIND(",", O23)+2, FIND(",", O23, FIND(",", O23)+1)-FIND(",", O23)-2)), "") | R23: =IFERROR(RIGHT(O23, LEN(O23)-FIND(",", O23, FIND(",", O23)+1)-1), "") | S23: {=_xlfn.TEXTJOIN(", ",TRUE,_xlfn._xlws.FILTER(Tabla29[[#All],[PARTE]],ISNUMBER(SEARCH(Tabla29[[#All],[PCLAVE3]],Tabla8[[#This Row],[DESCRIPCION DE TRABAJO]])),""))} -> Calibracion, Laminado | T23: =IF(AND(Tabla8[[#This Row],[PIEZA]]="",Tabla8[[#This Row],[PARTE]]=""),"VACIO","OK") -> VACIO | U23: =+CONCATENATE(WEEKNUM(Tabla8[[#This Row],[FECHA]]),"-",YEAR(Tabla8[[#This Row],[FECHA]])) -> 1-2025
A24: 45659 | B24: Omar Nina | C24: NOCHE | D24: 0.95555556 | E24: 0.96875 | F24: =+MOD(Tabla8[[#This Row],[HR. FIN]]-Tabla8[[#This Row],[HR. INICIO]],1) -> 0.013194444 | G24: MINIFLEX | H24: =IFERROR(VLOOKUP(G24,DATOS!$M$2:$N$219,2,FALSE),"") -> Maquinaria | I24: Ajuste /Calibracion | J24: =+VLOOKUP($I24,Tabla7[#All],2,FALSE) -> NO PROGRAMADA | K24: =IF(VLOOKUP(I24,Tabla7[#All],3,FALSE)=0,"",VLOOKUP(I24,Tabla7[#All],3,FALSE)) -> MECÁNICA | L24: Al sellar hace agujeros en la parte inferior de la caja | M24: Se cambio posicion de teflones de sellado, se hace preubas con producto. Queda operativo | N24: {=IFERROR(IF(Tabla8[[#This Row],[P/NP]]="NO PROGRAMADA","",_xlfn.TEXTJOIN(", ",TRUE,_xlfn._xlws.FILTER(Tabla4[[#All],[PIEZA]],ISNUMBER(SEARCH(Tabla4[[#All],[PCLAVE]],Tabla8[[#This Row],[DESCRIPCION DE TRABAJO]])),""))),"")} | O24: {=_xlfn.TEXTJOIN(", ",TRUE,_xlfn._xlws.FILTER(Tabla28[[#All],[PARTE]],ISNUMBER(SEARCH(Tabla28[[#All],[PCLAVE2]],Tabla8[[#This Row],[DESCRIPCION DE TRABAJO]])),""))} | P24: =IFERROR(LEFT(O24, FIND(",", O24)-1), O24) | Q24: =IFERROR(IF(ISERROR(FIND(",", O24, FIND(",", O24)+1)), RIGHT(O24, LEN(O24)-FIND(",", O24)-1), MID(O24, FIND(",", O24)+2, FIND(",", O24, FIND(",", O24)+1)-FIND(",", O24)-2)), "") | R24: =IFERROR(RIGHT(O24, LEN(O24)-FIND(",", O24, FIND(",", O24)+1)-1), "") | S24: {=_xlfn.TEXTJOIN(", ",TRUE,_xlfn._xlws.FILTER(Tabla29[[#All],[PARTE]],ISNUMBER(SEARCH(Tabla29[[#All],[PCLAVE3]],Tabla8[[#This Row],[DESCRIPCION DE TRABAJO]])),""))} -> Con Agujeros | T24: =IF(AND(Tabla8[[#This Row],[PIEZA]]="",Tabla8[[#This Row],[PARTE]]=""),"VACIO","OK") -> VACIO | U24: =+CONCATENATE(WEEKNUM(Tabla8[[#This Row],[FECHA]]),"-",YEAR(Tabla8[[#This Row],[FECHA]])) -> 1-2025
A25: 45659 | B25: Omar Nina | C25: NOCHE | D25: 1.0277778 | E25: 1.0402778 | F25: =+MOD(Tabla8[[#This Row],[HR. FIN]]-Tabla8[[#This Row],[HR. INICIO]],1) -> 0.0125 | G25: MOLINO REBOTE | H25: =IFERROR(VLOOKUP(G25,DATOS!$M$2:$N$219,2,FALSE),"") -> Maquinaria | I25: Limpieza | J25: =+VLOOKUP($I25,Tabla7[#All],2,FALSE) -> PROGRAMADA | K25: =IF(VLOOKUP(I25,Tabla7[#All],3,FALSE)=0,"",VLOOKUP(I25,Tabla7[#All],3,FALSE)) | L25: No deja encender, sale alarma | M25: Se limpio sensor y se encendio. Se deja trabajando | N25: {=IFERROR(IF(Tabla8[[#This Row],[P/NP]]="NO PROGRAMADA","",_xlfn.TEXTJOIN(", ",TRUE,_xlfn._xlws.FILTER(Tabla4[[#All],[PIEZA]],ISNUMBER(SEARCH(Tabla4[[#All],[PCLAVE]],Tabla8[[#This Row],[DESCRIPCION DE TRABAJO]])),""))),"")} | O25: {=_xlfn.TEXTJOIN(", ",TRUE,_xlfn._xlws.FILTER(Tabla28[[#All],[PARTE]],ISNUMBER(SEARCH(Tabla28[[#All],[PCLAVE2]],Tabla8[[#This Row],[DESCRIPCION DE TRABAJO]])),""))} | P25: =IFERROR(LEFT(O25, FIND(",", O25)-1), O25) | Q25: =IFERROR(IF(ISERROR(FIND(",", O25, FIND(",", O25)+1)), RIGHT(O25, LEN(O25)-FIND(",", O25)-1), MID(O25, FIND(",", O25)+2, FIND(",", O25, FIND(",", O25)+1)-FIND(",", O25)-2)), "") | R25: =IFERROR(RIGHT(O25, LEN(O25)-FIND(",", O25, FIND(",", O25)+1)-1), "") | S25: {=_xlfn.TEXTJOIN(", ",TRUE,_xlfn._xlws.FILTER(Tabla29[[#All],[PARTE]],ISNUMBER(SEARCH(Tabla29[[#All],[PCLAVE3]],Tabla8[[#This Row],[DESCRIPCION DE TRABAJO]])),""))} -> Alarma | T25: =IF(AND(Tabla8[[#This Row],[PIEZA]]="",Tabla8[[#This Row],[PARTE]]=""),"VACIO","OK") -> VACIO | U25: =+CONCATENATE(WEEKNUM(Tabla8[[#This Row],[FECHA]]),"-",YEAR(Tabla8[[#This Row],[FECHA]])) -> 1-2025
A26: 45659 | B26: Cesar Quiroz | C26: MAÑANA | D26: 0.47083333 | E26: 0.48333333 | F26: =+MOD(Tabla8[[#This Row],[HR. FIN]]-Tabla8[[#This Row],[HR. INICIO]],1) -> 0.0125 | G26: CYCLOP | H26: =IFERROR(VLOOKUP(G26,DATOS!$M$2:$N$219,2,FALSE),"") -> Maquinaria | I26: Inspección | J26: =+VLOOKUP($I26,Tabla7[#All],2,FALSE) -> PROGRAMADA | K26: =IF(VLOOKUP(I26,Tabla7[#All],3,FALSE)=0,"",VLOOKUP(I26,Tabla7[#All],3,FALSE)) | L26: Revision de funcionamiento | N26: {=IFERROR(IF(Tabla8[[#This Row],[P/NP]]="NO PROGRAMADA","",_xlfn.TEXTJOIN(", ",TRUE,_xlfn._xlws.FILTER(Tabla4[[#All],[PIEZA]],ISNUMBER(SEARCH(Tabla4[[#All],[PCLAVE]],Tabla8[[#This Row],[DESCRIPCION DE TRABAJO]])),""))),"")} | O26: {=_xlfn.TEXTJOIN(", ",TRUE,_xlfn._xlws.FILTER(Tabla28[[#All],[PARTE]],ISNUMBER(SEARCH(Tabla28[[#All],[PCLAVE2]],Tabla8[[#This Row],[DESCRIPCION DE TRABAJO]])),""))} | P26: =IFERROR(LEFT(O26, FIND(",", O26)-1), O26) | Q26: =IFERROR(IF(ISERROR(FIND(",", O26, FIND(",", O26)+1)), RIGHT(O26, LEN(O26)-FIND(",", O26)-1), MID(O26, FIND(",", O26)+2, FIND(",", O26, FIND(",", O26)+1)-FIND(",", O26)-2)), "") | R26: =IFERROR(RIGHT(O26, LEN(O26)-FIND(",", O26, FIND(",", O26)+1)-1), "") | S26: {=_xlfn.TEXTJOIN(", ",TRUE,_xlfn._xlws.FILTER(Tabla29[[#All],[PARTE]],ISNUMBER(SEARCH(Tabla29[[#All],[PCLAVE3]],Tabla8[[#This Row],[DESCRIPCION DE TRABAJO]])),""))} | T26: =IF(AND(Tabla8[[#This Row],[PIEZA]]="",Tabla8[[#This Row],[PARTE]]=""),"VACIO","OK") -> VACIO | U26: =+CONCATENATE(WEEKNUM(Tabla8[[#This Row],[FECHA]]),"-",YEAR(Tabla8[[#This Row],[FECHA]])) -> 1-2025
A27: 45659 | B27: Cesar Quiroz | C27: MAÑANA | D27: 0.39305556 | E27: 0.40555556 | F27: =+MOD(Tabla8[[#This Row],[HR. FIN]]-Tabla8[[#This Row],[HR. INICIO]],1) -> 0.0125 | G27: EMP. FLOWPACK 2 | H27: =IFERROR(VLOOKUP(G27,DATOS!$M$2:$N$219,2,FALSE),"") -> Maquinaria | I27: Ajuste /Calibracion | J27: =+VLOOKUP($I27,Tabla7[#All],2,FALSE) -> NO PROGRAMADA | K27: =IF(VLOOKUP(I27,Tabla7[#All],3,FALSE)=0,"",VLOOKUP(I27,Tabla7[#All],3,FALSE)) -> MECÁNICA | L27: Alineacion de guiadores, regularizacion de sensor | N27: {=IFERROR(IF(Tabla8[[#This Row],[P/NP]]="NO PROGRAMADA","",_xlfn.TEXTJOIN(", ",TRUE,_xlfn._xlws.FILTER(Tabla4[[#All],[PIEZA]],ISNUMBER(SEARCH(Tabla4[[#All],[PCLAVE]],Tabla8[[#This Row],[DESCRIPCION DE TRABAJO]])),""))),"")} | O27: {=_xlfn.TEXTJOIN(", ",TRUE,_xlfn._xlws.FILTER(Tabla28[[#All],[PARTE]],ISNUMBER(SEARCH(Tabla28[[#All],[PCLAVE2]],Tabla8[[#This Row],[DESCRIPCION DE TRABAJO]])),""))} | P27: =IFERROR(LEFT(O27, FIND(",", O27)-1), O27) | Q27: =IFERROR(IF(ISERROR(FIND(",", O27, FIND(",", O27)+1)), RIGHT(O27, LEN(O27)-FIND(",", O27)-1), MID(O27, FIND(",", O27)+2, FIND(",", O27, FIND(",", O27)+1)-FIND(",", O27)-2)), "") | R27: =IFERROR(RIGHT(O27, LEN(O27)-FIND(",", O27, FIND(",", O27)+1)-1), "") | S27: {=_xlfn.TEXTJOIN(", ",TRUE,_xlfn._xlws.FILTER(Tabla29[[#All],[PARTE]],ISNUMBER(SEARCH(Tabla29[[#All],[PCLAVE3]],Tabla8[[#This Row],[DESCRIPCION DE TRABAJO]])),""))} -> Desalineado | T27: =IF(AND(Tabla8[[#This Row],[PIEZA]]="",Tabla8[[#This Row],[PARTE]]=""),"VACIO","OK") -> VACIO | U27: =+CONCATENATE(WEEKNUM(Tabla8[[#This Row],[FECHA]]),"-",YEAR(Tabla8[[#This Row],[FECHA]])) -> 1-2025
A28: 45659 | B28: Carlos Puma | C28: TARDE | D28: 0.54166667 | E28: 0.55208333 | F28: =+MOD(Tabla8[[#This Row],[HR. FIN]]-Tabla8[[#This Row],[HR. INICIO]],1) -> 0.010416667 | G28: NETCH | H28: =IFERROR(VLOOKUP(G28,DATOS!$M$2:$N$219,2,FALSE),"") -> Maquinaria | I28: SET UP | J28: =+VLOOKUP($I28,Tabla7[#All],2,FALSE) -> PROGRAMADA | K28: =IF(VLOOKUP(I28,Tabla7[#All],3,FALSE)=0,"",VLOOKUP(I28,Tabla7[#All],3,FALSE)) | L28: Armado de equipo | N28: {=IFERROR(IF(Tabla8[[#This Row],[P/NP]]="NO PROGRAMADA","",_xlfn.TEXTJOIN(", ",TRUE,_xlfn._xlws.FILTER(Tabla4[[#All],[PIEZA]],ISNUMBER(SEARCH(Tabla4[[#All],[PCLAVE]],Tabla8[[#This Row],[DESCRIPCION DE TRABAJO]])),""))),"")} | O28: {=_xlfn.TEXTJOIN(", ",TRUE,_xlfn._xlws.FILTER(Tabla28[[#All],[PARTE]],ISNUMBER(SEARCH(Tabla28[[#All],[PCLAVE2]],Tabla8[[#This Row],[DESCRIPCION DE TRABAJO]])),""))} | P28: =IFERROR(LEFT(O28, FIND(",", O28)-1), O28) | Q28: =IFERROR(IF(ISERROR(FIND(",", O28, FIND(",", O28)+1)), RIGHT(O28, LEN(O28)-FIND(",", O28)-1), MID(O28, FIND(",", O28)+2, FIND(",", O28, FIND(",", O28)+1)-FIND(",", O28)-2)), "") | R28: =IFERROR(RIGHT(O28, LEN(O28)-FIND(",", O28, FIND(",", O28)+1)-1), "") | S28: {=_xlfn.TEXTJOIN(", ",TRUE,_xlfn._xlws.FILTER(Tabla29[[#All],[PARTE]],ISNUMBER(SEARCH(Tabla29[[#All],[PCLAVE3]],Tabla8[[#This Row],[DESCRIPCION DE TRABAJO]])),""))} | T28: =IF(AND(Tabla8[[#This Row],[PIEZA]]="",Tabla8[[#This Row],[PARTE]]=""),"VACIO","OK") -> VACIO | U28: =+CONCATENATE(WEEKNUM(Tabla8[[#This Row],[FECHA]]),"-",YEAR(Tabla8[[#This Row],[FECHA]])) -> 1-2025
A29: 45659 | B29: Carlos Puma | C29: TARDE | D29: 0.85416667 | E29: 0.86458333 | F29: =+MOD(Tabla8[[#This Row],[HR. FIN]]-Tabla8[[#This Row],[HR. INICIO]],1) -> 0.010416667 | G29: GIANINI 1 - FAMAIC | H29: =IFERROR(VLOOKUP(G29,DATOS!$M$2:$N$219,2,FALSE),"") -> Maquinaria | I29: Inspección | J29: =+VLOOKUP($I29,Tabla7[#All],2,FALSE) -> PROGRAMADA | K29: =IF(VLOOKUP(I29,Tabla7[#All],3,FALSE)=0,"",VLOOKUP(I29,Tabla7[#All],3,FALSE)) | L29: Ruido al girar | M29: Se realizo pruebas y del ruido nose manifesto (ruido intermitente) | N29: {=IFERROR(IF(Tabla8[[#This Row],[P/NP]]="NO PROGRAMADA","",_xlfn.TEXTJOIN(", ",TRUE,_xlfn._xlws.FILTER(Tabla4[[#All],[PIEZA]],ISNUMBER(SEARCH(Tabla4[[#All],[PCLAVE]],Tabla8[[#This Row],[DESCRIPCION DE TRABAJO]])),""))),"")} | O29: {=_xlfn.TEXTJOIN(", ",TRUE,_xlfn._xlws.FILTER(Tabla28[[#All],[PARTE]],ISNUMBER(SEARCH(Tabla28[[#All],[PCLAVE2]],Tabla8[[#This Row],[DESCRIPCION DE TRABAJO]])),""))} | P29: =IFERROR(LEFT(O29, FIND(",", O29)-1), O29) | Q29: =IFERROR(IF(ISERROR(FIND(",", O29, FIND(",", O29)+1)), RIGHT(O29, LEN(O29)-FIND(",", O29)-1), MID(O29, FIND(",", O29)+2, FIND(",", O29, FIND(",", O29)+1)-FIND(",", O29)-2)), "") | R29: =IFERROR(RIGHT(O29, LEN(O29)-FIND(",", O29, FIND(",", O29)+1)-1), "") | S29: {=_xlfn.TEXTJOIN(", ",TRUE,_xlfn._xlws.FILTER(Tabla29[[#All],[PARTE]],ISNUMBER(SEARCH(Tabla29[[#All],[PCLAVE3]],Tabla8[[#This Row],[DESCRIPCION DE TRABAJO]])),""))} -> Ruido | T29: =IF(AND(Tabla8[[#This Row],[PIEZA]]="",Tabla8[[#This Row],[PARTE]]=""),"VACIO","OK") -> VACIO | U29: =+CONCATENATE(WEEKNUM(Tabla8[[#This Row],[FECHA]]),"-",YEAR(Tabla8[[#This Row],[FECHA]])) -> 1-2025
A30: 45659 | B30: Carlos Puma | C30: TARDE | D30: 0.78125 | E30: 0.79166667 | F30: =+MOD(Tabla8[[#This Row],[HR. FIN]]-Tabla8[[#This Row],[HR. INICIO]],1) -> 0.010416667 | G30: HACOS 1 | H30: =IFERROR(VLOOKUP(G30,DATOS!$M$2:$N$219,2,FALSE),"") -> Maquinaria | I30: Inspección | J30: =+VLOOKUP($I30,Tabla7[#All],2,FALSE) -> PROGRAMADA | K30: =IF(VLOOKUP(I30,Tabla7[#All],3,FALSE)=0,"",VLOOKUP(I30,Tabla7[#All],3,FALSE)) | L30: Inspeccion de equipo (piston C-14) | N30: {=IFERROR(IF(Tabla8[[#This Row],[P/NP]]="NO PROGRAMADA","",_xlfn.TEXTJOIN(", ",TRUE,_xlfn._xlws.FILTER(Tabla4[[#All],[PIEZA]],ISNUMBER(SEARCH(Tabla4[[#All],[PCLAVE]],Tabla8[[#This Row],[DESCRIPCION DE TRABAJO]])),""))),"")} -> Piston(es) | O30: {=_xlfn.TEXTJOIN(", ",TRUE,_xlfn._xlws.FILTER(Tabla28[[#All],[PARTE]],ISNUMBER(SEARCH(Tabla28[[#All],[PCLAVE2]],Tabla8[[#This Row],[DESCRIPCION DE TRABAJO]])),""))} | P30: =IFERROR(LEFT(O30, FIND(",", O30)-1), O30) | Q30: =IFERROR(IF(ISERROR(FIND(",", O30, FIND(",", O30)+1)), RIGHT(O30, LEN(O30)-FIND(",", O30)-1), MID(O30, FIND(",", O30)+2, FIND(",", O30, FIND(",", O30)+1)-FIND(",", O30)-2)), "") | R30: =IFERROR(RIGHT(O30, LEN(O30)-FIND(",", O30, FIND(",", O30)+1)-1), "") | S30: {=_xlfn.TEXTJOIN(", ",TRUE,_xlfn._xlws.FILTER(Tabla29[[#All],[PARTE]],ISNUMBER(SEARCH(Tabla29[[#All],[PCLAVE3]],Tabla8[[#This Row],[DESCRIPCION DE TRABAJO]])),""))} | T30: =IF(AND(Tabla8[[#This Row],[PIEZA]]="",Tabla8[[#This Row],[PARTE]]=""),"VACIO","OK") -> OK | U30: =+CONCATENATE(WEEKNUM(Tabla8[[#This Row],[FECHA]]),"-",YEAR(Tabla8[[#This Row],[FECHA]])) -> 1-2025
A31: 45659 | B31: Omar Nina | C31: NOCHE | D31: 1.0138889 | E31: 1.0236111 | F31: =+MOD(Tabla8[[#This Row],[HR. FIN]]-Tabla8[[#This Row],[HR. INICIO]],1) -> 0.0097222222 | G31: EMP. AMP ROSE | H31: =IFERROR(VLOOKUP(G31,DATOS!$M$2:$N$219,2,FALSE),"") -> Maquinaria | I31: Ajuste /Calibracion | J31: =+VLOOKUP($I31,Tabla7[#All],2,FALSE) -> NO PROGRAMADA | K31: =IF(VLOOKUP(I31,Tabla7[#All],3,FALSE)=0,"",VLOOKUP(I31,Tabla7[#All],3,FALSE)) -> MECÁNICA | L31: Cuchilla no corta | M31: Se calibro cuchilla | N31: {=IFERROR(IF(Tabla8[[#This Row],[P/NP]]="NO PROGRAMADA","",_xlfn.TEXTJOIN(", ",TRUE,_xlfn._xlws.FILTER(Tabla4[[#All],[PIEZA]],ISNUMBER(SEARCH(Tabla4[[#All],[PCLAVE]],Tabla8[[#This Row],[DESCRIPCION DE TRABAJO]])),""))),"")} | O31: {=_xlfn.TEXTJOIN(", ",TRUE,_xlfn._xlws.FILTER(Tabla28[[#All],[PARTE]],ISNUMBER(SEARCH(Tabla28[[#All],[PCLAVE2]],Tabla8[[#This Row],[DESCRIPCION DE TRABAJO]])),""))} | P31: =IFERROR(LEFT(O31, FIND(",", O31)-1), O31) | Q31: =IFERROR(IF(ISERROR(FIND(",", O31, FIND(",", O31)+1)), RIGHT(O31, LEN(O31)-FIND(",", O31)-1), MID(O31, FIND(",", O31)+2, FIND(",", O31, FIND(",", O31)+1)-FIND(",", O31)-2)), "") | R31: =IFERROR(RIGHT(O31, LEN(O31)-FIND(",", O31, FIND(",", O31)+1)-1), "") | S31: {=_xlfn.TEXTJOIN(", ",TRUE,_xlfn._xlws.FILTER(Tabla29[[#All],[PARTE]],ISNUMBER(SEARCH(Tabla29[[#All],[PCLAVE3]],Tabla8[[#This Row],[DESCRIPCION DE TRABAJO]])),""))} -> No Corta | T31: =IF(AND(Tabla8[[#This Row],[PIEZA]]="",Tabla8[[#This Row],[PARTE]]=""),"VACIO","OK") -> VACIO | U31: =+CONCATENATE(WEEKNUM(Tabla8[[#This Row],[FECHA]]),"-",YEAR(Tabla8[[#This Row],[FECHA]])) -> 1-2025
A32: 45659 | B32: Cesar Quiroz | C32: MAÑANA | D32: 0.36666667 | E32: 0.37430556 | F32: =+MOD(Tabla8[[#This Row],[HR. FIN]]-Tabla8[[#This Row],[HR. INICIO]],1) -> 0.0076388889 | G32: HACOS 1 | H32: =IFERROR(VLOOKUP(G32,DATOS!$M$2:$N$219,2,FALSE),"") -> Maquinaria | I32: Inspección | J32: =+VLOOKUP($I32,Tabla7[#All],2,FALSE) -> PROGRAMADA | K32: =IF(VLOOKUP(I32,Tabla7[#All],3,FALSE)=0,"",VLOOKUP(I32,Tabla7[#All],3,FALSE)) | L32: Temperatura de columnas se baja | M32: Se reviso nivel de agua de tanque. Se reviso retorno, se modifico seteado de agua fria, se modifico velocidad de bomba | N32: {=IFERROR(IF(Tabla8[[#This Row],[P/NP]]="NO PROGRAMADA","",_xlfn.TEXTJOIN(", ",TRUE,_xlfn._xlws.FILTER(Tabla4[[#All],[PIEZA]],ISNUMBER(SEARCH(Tabla4[[#All],[PCLAVE]],Tabla8[[#This Row],[DESCRIPCION DE TRABAJO]])),""))),"")} | O32: {=_xlfn.TEXTJOIN(", ",TRUE,_xlfn._xlws.FILTER(Tabla28[[#All],[PARTE]],ISNUMBER(SEARCH(Tabla28[[#All],[PCLAVE2]],Tabla8[[#This Row],[DESCRIPCION DE TRABAJO]])),""))} -> Columna | P32: =IFERROR(LEFT(O32, FIND(",", O32)-1), O32) -> Columna | Q32: =IFERROR(IF(ISERROR(FIND(",", O32, FIND(",", O32)+1)), RIGHT(O32, LEN(O32)-FIND(",", O32)-1), MID(O32, FIND(",", O32)+2, FIND(",", O32, FIND(",", O32)+1)-FIND(",", O32)-2)), "") | R32: =IFERROR(RIGHT(O32, LEN(O32)-FIND(",", O32, FIND(",", O32)+1)-1), "") | S32: {=_xlfn.TEXTJOIN(", ",TRUE,_xlfn._xlws.FILTER(Tabla29[[#All],[PARTE]],ISNUMBER(SEARCH(Tabla29[[#All],[PCLAVE3]],Tabla8[[#This Row],[DESCRIPCION DE TRABAJO]])),""))} | T32: =IF(AND(Tabla8[[#This Row],[PIEZA]]="",Tabla8[[#This Row],[PARTE]]=""),"VACIO","OK") -> OK | U32: =+CONCATENATE(WEEKNUM(Tabla8[[#This Row],[FECHA]]),"-",YEAR(Tabla8[[#This Row],[FECHA]])) -> 1-2025
A33: 45659 | B33: Carlos Puma | C33: TARDE | D33: 0.60069444 | E33: 0.60763889 | F33: =+MOD(Tabla8[[#This Row],[HR. FIN]]-Tabla8[[#This Row],[HR. INICIO]],1) -> 0.0069444444 | G33: BAÑADORA DE CHOCOLATES 1 | H33: =IFERROR(VLOOKUP(G33,DATOS!$M$2:$N$219,2,FALSE),"") -> Maquinaria | I33: Limpieza | J33: =+VLOOKUP($I33,Tabla7[#All],2,FALSE) -> PROGRAMADA | K33: =IF(VLOOKUP(I33,Tabla7[#All],3,FALSE)=0,"",VLOOKUP(I33,Tabla7[#All],3,FALSE)) | L33: Se retiro filtro para limpieza | N33: {=IFERROR(IF(Tabla8[[#This Row],[P/NP]]="NO PROGRAMADA","",_xlfn.TEXTJOIN(", ",TRUE,_xlfn._xlws.FILTER(Tabla4[[#All],[PIEZA]],ISNUMBER(SEARCH(Tabla4[[#All],[PCLAVE]],Tabla8[[#This Row],[DESCRIPCION DE TRABAJO]])),""))),"")} -> Filtro | O33: {=_xlfn.TEXTJOIN(", ",TRUE,_xlfn._xlws.FILTER(Tabla28[[#All],[PARTE]],ISNUMBER(SEARCH(Tabla28[[#All],[PCLAVE2]],Tabla8[[#This Row],[DESCRIPCION DE TRABAJO]])),""))} | P33: =IFERROR(LEFT(O33, FIND(",", O33)-1), O33) | Q33: =IFERROR(IF(ISERROR(FIND(",", O33, FIND(",", O33)+1)), RIGHT(O33, LEN(O33)-FIND(",", O33)-1), MID(O33, FIND(",", O33)+2, FIND(",", O33, FIND(",", O33)+1)-FIND(",", O33)-2)), "") | R33: =IFERROR(RIGHT(O33, LEN(O33)-FIND(",", O33, FIND(",", O33)+1)-1), "") | S33: {=_xlfn.TEXTJOIN(", ",TRUE,_xlfn._xlws.FILTER(Tabla29[[#All],[PARTE]],ISNUMBER(SEARCH(Tabla29[[#All],[PCLAVE3]],Tabla8[[#This Row],[DESCRIPCION DE TRABAJO]])),""))} -> Filtracion, Sustitucion | T33: =IF(AND(Tabla8[[#This Row],[PIEZA]]="",Tabla8[[#This Row],[PARTE]]=""),"VACIO","OK") -> OK | U33: =+CONCATENATE(WEEKNUM(Tabla8[[#This Row],[FECHA]]),"-",YEAR(Tabla8[[#This Row],[FECHA]])) -> 1-2025
A34: 46027 | B34: CARLOS TAPIA | C34: MAÑANA | D34: 08:30 | E34: 09:50 | F34: =+MOD(Tabla8[[#This Row],[HR. FIN]]-Tabla8[[#This Row],[HR. INICIO]],1) -> 0.055555556 | G34: 1ER PISO | H34: =IFERROR(VLOOKUP(G34,DATOS!$M$2:$N$219,2,FALSE),"") -> Area | I34: SET UP | J34: NO PROGRAMADA | K34: MECÁNICA | L34: Bomba del tanque de retorno se encuentra obstruida. | M34: Se retiró tuberías conectadas a bomba y se retiró el trapeador que se encontraba obstruyendo el impulsor. | N34: {=IFERROR(IF(Tabla8[[#This Row],[P/NP]]="NO PROGRAMADA","",_xlfn.TEXTJOIN(", ",TRUE,_xlfn._xlws.FILTER(Tabla4[[#All],[PIEZA]],ISNUMBER(SEARCH(Tabla4[[#All],[PCLAVE]],Tabla8[[#This Row],[DESCRIPCION DE TRABAJO]])),""))),"")} | O34: {=_xlfn.TEXTJOIN(", ",TRUE,_xlfn._xlws.FILTER(Tabla28[[#All],[PARTE]],ISNUMBER(SEARCH(Tabla28[[#All],[PCLAVE2]],Tabla8[[#This Row],[DESCRIPCION DE TRABAJO]])),""))} -> Tanque | P34: =IFERROR(LEFT(O34, FIND(",", O34)-1), O34) -> Tanque | Q34: =IFERROR(IF(ISERROR(FIND(",", O34, FIND(",", O34)+1)), RIGHT(O34, LEN(O34)-FIND(",", O34)-1), MID(O34, FIND(",", O34)+2, FIND(",", O34, FIND(",", O34)+1)-FIND(",", O34)-2)), "") | R34: =IFERROR(RIGHT(O34, LEN(O34)-FIND(",", O34, FIND(",", O34)+1)-1), "") | S34: {=_xlfn.TEXTJOIN(", ",TRUE,_xlfn._xlws.FILTER(Tabla29[[#All],[PARTE]],ISNUMBER(SEARCH(Tabla29[[#All],[PCLAVE3]],Tabla8[[#This Row],[DESCRIPCION DE TRABAJO]])),""))} -> Obstruido, Ruido | T34: =IF(AND(Tabla8[[#This Row],[PIEZA]]="",Tabla8[[#This Row],[PARTE]]=""),"VACIO","OK") -> OK | U34: =+CONCATENATE(WEEKNUM(Tabla8[[#This Row],[FECHA]]),"-",YEAR(Tabla8[[#This Row],[FECHA]])) -> 2-2026
A35: 46027 | B35: CARLOS TAPIA | C35: MAÑANA | D35: 10:00 | E35: 11:00 | F35: =+MOD(Tabla8[[#This Row],[HR. FIN]]-Tabla8[[#This Row],[HR. INICIO]],1) -> 0.041666667 | G35: BARQUILLERA FRANZ HAAZ | H35: =IFERROR(VLOOKUP(G35,DATOS!$M$2:$N$219,2,FALSE),"") -> Maquinaria | I35: SET UP | J35: =+VLOOKUP($I35,Tabla7[#All],2,FALSE) -> PROGRAMADA | K35: =IF(VLOOKUP(I35,Tabla7[#All],3,FALSE)=0,"",VLOOKUP(I35,Tabla7[#All],3,FALSE)) | L35: Armar máquina para el turno tarde. | M35: Se colocó piezas en posición y se dejó habilitada para el turno tarde. | N35: {=IFERROR(IF(Tabla8[[#This Row],[P/NP]]="NO PROGRAMADA","",_xlfn.TEXTJOIN(", ",TRUE,_xlfn._xlws.FILTER(Tabla4[[#All],[PIEZA]],ISNUMBER(SEARCH(Tabla4[[#All],[PCLAVE]],Tabla8[[#This Row],[DESCRIPCION DE TRABAJO]])),""))),"")} | O35: {=_xlfn.TEXTJOIN(", ",TRUE,_xlfn._xlws.FILTER(Tabla28[[#All],[PARTE]],ISNUMBER(SEARCH(Tabla28[[#All],[PCLAVE2]],Tabla8[[#This Row],[DESCRIPCION DE TRABAJO]])),""))} | P35: =IFERROR(LEFT(O35, FIND(",", O35)-1), O35) | Q35: =IFERROR(IF(ISERROR(FIND(",", O35, FIND(",", O35)+1)), RIGHT(O35, LEN(O35)-FIND(",", O35)-1), MID(O35, FIND(",", O35)+2, FIND(",", O35, FIND(",", O35)+1)-FIND(",", O35)-2)), "") | R35: =IFERROR(RIGHT(O35, LEN(O35)-FIND(",", O35, FIND(",", O35)+1)-1), "") | S35: {=_xlfn.TEXTJOIN(", ",TRUE,_xlfn._xlws.FILTER(Tabla29[[#All],[PARTE]],ISNUMBER(SEARCH(Tabla29[[#All],[PCLAVE3]],Tabla8[[#This Row],[DESCRIPCION DE TRABAJO]])),""))} | T35: =IF(AND(Tabla8[[#This Row],[PIEZA]]="",Tabla8[[#This Row],[PARTE]]=""),"VACIO","OK") -> VACIO | U35: =+CONCATENATE(WEEKNUM(Tabla8[[#This Row],[FECHA]]),"-",YEAR(Tabla8[[#This Row],[FECHA]])) -> 2-2026
A36: 46027 | B36: CARLOS TAPIA | C36: MAÑANA | D36: 05:30 | E36: 06:20 | F36: =+MOD(Tabla8[[#This Row],[HR. FIN]]-Tabla8[[#This Row],[HR. INICIO]],1) -> 0.034722222 | G36: PLANTA INDUSTRIAL | H36: =IFERROR(VLOOKUP(G36,DATOS!$M$2:$N$219,2,FALSE),"") -> Area | I36: Encendido / Arranque de linea | J36: =+VLOOKUP($I36,Tabla7[#All],2,FALSE) -> PROGRAMADA | K36: =IF(VLOOKUP(I36,Tabla7[#All],3,FALSE)=0,"",VLOOKUP(I36,Tabla7[#All],3,FALSE)) | L36: Arranque de planta. | M36: Se encendió líneas de vapor agua y aire. Se revisó y encendió equipos. | N36: {=IFERROR(IF(Tabla8[[#This Row],[P/NP]]="NO PROGRAMADA","",_xlfn.TEXTJOIN(", ",TRUE,_xlfn._xlws.FILTER(Tabla4[[#All],[PIEZA]],ISNUMBER(SEARCH(Tabla4[[#All],[PCLAVE]],Tabla8[[#This Row],[DESCRIPCION DE TRABAJO]])),""))),"")} | O36: {=_xlfn.TEXTJOIN(", ",TRUE,_xlfn._xlws.FILTER(Tabla28[[#All],[PARTE]],ISNUMBER(SEARCH(Tabla28[[#All],[PCLAVE2]],Tabla8[[#This Row],[DESCRIPCION DE TRABAJO]])),""))} | P36: =IFERROR(LEFT(O36, FIND(",", O36)-1), O36) | Q36: =IFERROR(IF(ISERROR(FIND(",", O36, FIND(",", O36)+1)), RIGHT(O36, LEN(O36)-FIND(",", O36)-1), MID(O36, FIND(",", O36)+2, FIND(",", O36, FIND(",", O36)+1)-FIND(",", O36)-2)), "") | R36: =IFERROR(RIGHT(O36, LEN(O36)-FIND(",", O36, FIND(",", O36)+1)-1), "") | S36: {=_xlfn.TEXTJOIN(", ",TRUE,_xlfn._xlws.FILTER(Tabla29[[#All],[PARTE]],ISNUMBER(SEARCH(Tabla29[[#All],[PCLAVE3]],Tabla8[[#This Row],[DESCRIPCION DE TRABAJO]])),""))} | T36: =IF(AND(Tabla8[[#This Row],[PIEZA]]="",Tabla8[[#This Row],[PARTE]]=""),"VACIO","OK") -> VACIO | U36: =+CONCATENATE(WEEKNUM(Tabla8[[#This Row],[FECHA]]),"-",YEAR(Tabla8[[#This Row],[FECHA]])) -> 2-2026
A37: 46027 | B37: CARLOS TAPIA | C37: MAÑANA | D37: 12:40 | E37: 13:30 | F37: =+MOD(Tabla8[[#This Row],[HR. FIN]]-Tabla8[[#This Row],[HR. INICIO]],1) -> 0.034722222 | G37: COCINADORA 3 - GIANNINI | H37: =IFERROR(VLOOKUP(G37,DATOS!$M$2:$N$219,2,FALSE),"") -> Maquinaria | I37: Sustitucion | J37: =+VLOOKUP($I37,Tabla7[#All],2,FALSE) -> NO PROGRAMADA | K37: MECÁNICA | L37: Fuga de vapor por empaque (brida). | M37: Se retiró brida para el reemplazo de empaque. Se dejó operativa. | N37: {=IFERROR(IF(Tabla8[[#This Row],[P/NP]]="NO PROGRAMADA","",_xlfn.TEXTJOIN(", ",TRUE,_xlfn._xlws.FILTER(Tabla4[[#All],[PIEZA]],ISNUMBER(SEARCH(Tabla4[[#All],[PCLAVE]],Tabla8[[#This Row],[DESCRIPCION DE TRABAJO]])),""))),"")} | O37: {=_xlfn.TEXTJOIN(", ",TRUE,_xlfn._xlws.FILTER(Tabla28[[#All],[PARTE]],ISNUMBER(SEARCH(Tabla28[[#All],[PCLAVE2]],Tabla8[[#This Row],[DESCRIPCION DE TRABAJO]])),""))} | P37: =IFERROR(LEFT(O37, FIND(",", O37)-1), O37) | Q37: =IFERROR(IF(ISERROR(FIND(",", O37, FIND(",", O37)+1)), RIGHT(O37, LEN(O37)-FIND(",", O37)-1), MID(O37, FIND(",", O37)+2, FIND(",", O37, FIND(",", O37)+1)-FIND(",", O37)-2)), "") | R37: =IFERROR(RIGHT(O37, LEN(O37)-FIND(",", O37, FIND(",", O37)+1)-1), "") | S37: {=_xlfn.TEXTJOIN(", ",TRUE,_xlfn._xlws.FILTER(Tabla29[[#All],[PARTE]],ISNUMBER(SEARCH(Tabla29[[#All],[PCLAVE3]],Tabla8[[#This Row],[DESCRIPCION DE TRABAJO]])),""))} -> Fuga | T37: =IF(AND(Tabla8[[#This Row],[PIEZA]]="",Tabla8[[#This Row],[PARTE]]=""),"VACIO","OK") -> VACIO | U37: =+CONCATENATE(WEEKNUM(Tabla8[[#This Row],[FECHA]]),"-",YEAR(Tabla8[[#This Row],[FECHA]])) -> 2-2026
A38: 46027 | B38: CARLOS PUMA | C38: NOCHE | D38: 01:00 | E38: 01:45 | F38: =+MOD(Tabla8[[#This Row],[HR. FIN]]-Tabla8[[#This Row],[HR. INICIO]],1) -> 0.03125 | G38: QUEBRANTADOR DE CACAO 01 JAF INOX | H38: =IFERROR(VLOOKUP(G38,DATOS!$M$2:$N$219,2,FALSE),"") -> Maquinaria | I38: Ajuste /Calibracion | J38: =+VLOOKUP($I38,Tabla7[#All],2,FALSE) -> NO PROGRAMADA | K38: =IF(VLOOKUP(I38,Tabla7[#All],3,FALSE)=0,"",VLOOKUP(I38,Tabla7[#All],3,FALSE)) -> MECÁNICA | L38: Problemas con aspiración de ciclo jafinox , | M38: Se invirtió el giro de motor de aspiración y de motor de salida de cascarilla , se reviso circuito eléctrico y se realizó un puente ala bobina del contactor de motor de salida para habilitar el encendido con interruptor del teblero | N38: {=IFERROR(IF(Tabla8[[#This Row],[P/NP]]="NO PROGRAMADA","",_xlfn.TEXTJOIN(", ",TRUE,_xlfn._xlws.FILTER(Tabla4[[#All],[PIEZA]],ISNUMBER(SEARCH(Tabla4[[#All],[PCLAVE]],Tabla8[[#This Row],[DESCRIPCION DE TRABAJO]])),""))),"")} | O38: {=_xlfn.TEXTJOIN(", ",TRUE,_xlfn._xlws.FILTER(Tabla28[[#All],[PARTE]],ISNUMBER(SEARCH(Tabla28[[#All],[PCLAVE2]],Tabla8[[#This Row],[DESCRIPCION DE TRABAJO]])),""))} | P38: =IFERROR(LEFT(O38, FIND(",", O38)-1), O38) | Q38: =IFERROR(IF(ISERROR(FIND(",", O38, FIND(",", O38)+1)), RIGHT(O38, LEN(O38)-FIND(",", O38)-1), MID(O38, FIND(",", O38)+2, FIND(",", O38, FIND(",", O38)+1)-FIND(",", O38)-2)), "") | R38: =IFERROR(RIGHT(O38, LEN(O38)-FIND(",", O38, FIND(",", O38)+1)-1), "") | S38: {=_xlfn.TEXTJOIN(", ",TRUE,_xlfn._xlws.FILTER(Tabla29[[#All],[PARTE]],ISNUMBER(SEARCH(Tabla29[[#All],[PCLAVE3]],Tabla8[[#This Row],[DESCRIPCION DE TRABAJO]])),""))} | T38: =IF(AND(Tabla8[[#This Row],[PIEZA]]="",Tabla8[[#This Row],[PARTE]]=""),"VACIO","OK") -> VACIO | U38: =+CONCATENATE(WEEKNUM(Tabla8[[#This Row],[FECHA]]),"-",YEAR(Tabla8[[#This Row],[FECHA]])) -> 2-2026
A39: 46027 | B39: CARLOS PUMA | C39: NOCHE | D39: 21:55 | E39: 22:25 | F39: =+MOD(Tabla8[[#This Row],[HR. FIN]]-Tabla8[[#This Row],[HR. INICIO]],1) -> 0.020833333 | G39: LINEA AUTOMATICA HACOS 1 | H39: =IFERROR(VLOOKUP(G39,DATOS!$M$2:$N$219,2,FALSE),"") -> Maquinaria | I39: SET UP | J39: =+VLOOKUP($I39,Tabla7[#All],2,FALSE) -> PROGRAMADA | K39: =IF(VLOOKUP(I39,Tabla7[#All],3,FALSE)=0,"",VLOOKUP(I39,Tabla7[#All],3,FALSE)) | L39: Armado de mds para formato crema ovalada | N39: {=IFERROR(IF(Tabla8[[#This Row],[P/NP]]="NO PROGRAMADA","",_xlfn.TEXTJOIN(", ",TRUE,_xlfn._xlws.FILTER(Tabla4[[#All],[PIEZA]],ISNUMBER(SEARCH(Tabla4[[#All],[PCLAVE]],Tabla8[[#This Row],[DESCRIPCION DE TRABAJO]])),""))),"")} | O39: {=_xlfn.TEXTJOIN(", ",TRUE,_xlfn._xlws.FILTER(Tabla28[[#All],[PARTE]],ISNUMBER(SEARCH(Tabla28[[#All],[PCLAVE2]],Tabla8[[#This Row],[DESCRIPCION DE TRABAJO]])),""))} -> Mds | P39: =IFERROR(LEFT(O39, FIND(",", O39)-1), O39) -> Mds | Q39: =IFERROR(IF(ISERROR(FIND(",", O39, FIND(",", O39)+1)), RIGHT(O39, LEN(O39)-FIND(",", O39)-1), MID(O39, FIND(",", O39)+2, FIND(",", O39, FIND(",", O39)+1)-FIND(",", O39)-2)), "") | R39: =IFERROR(RIGHT(O39, LEN(O39)-FIND(",", O39, FIND(",", O39)+1)-1), "") | S39: {=_xlfn.TEXTJOIN(", ",TRUE,_xlfn._xlws.FILTER(Tabla29[[#All],[PARTE]],ISNUMBER(SEARCH(Tabla29[[#All],[PCLAVE3]],Tabla8[[#This Row],[DESCRIPCION DE TRABAJO]])),""))} -> Cambio De Formato | T39: =IF(AND(Tabla8[[#This Row],[PIEZA]]="",Tabla8[[#This Row],[PARTE]]=""),"VACIO","OK") -> OK | U39: =+CONCATENATE(WEEKNUM(Tabla8[[#This Row],[FECHA]]),"-",YEAR(Tabla8[[#This Row],[FECHA]])) -> 2-2026
A40: 46027 | B40: CARLOS TAPIA | C40: MAÑANA | D40: 06:30 | E40: 07:00 | F40: =+MOD(Tabla8[[#This Row],[HR. FIN]]-Tabla8[[#This Row],[HR. INICIO]],1) -> 0.020833333 | G40: LINEA AUTOMATICA HACOS 1 | H40: =IFERROR(VLOOKUP(G40,DATOS!$M$2:$N$219,2,FALSE),"") -> Maquinaria | I40: SET UP | J40: =+VLOOKUP($I40,Tabla7[#All],2,FALSE) -> PROGRAMADA | K40: =IF(VLOOKUP(I40,Tabla7[#All],3,FALSE)=0,"",VLOOKUP(I40,Tabla7[#All],3,FALSE)) | L40: Desarmar módulo MDS para su limpieza. | M40: Se desarmo módulo de MDS. | N40: {=IFERROR(IF(Tabla8[[#This Row],[P/NP]]="NO PROGRAMADA","",_xlfn.TEXTJOIN(", ",TRUE,_xlfn._xlws.FILTER(Tabla4[[#All],[PIEZA]],ISNUMBER(SEARCH(Tabla4[[#All],[PCLAVE]],Tabla8[[#This Row],[DESCRIPCION DE TRABAJO]])),""))),"")} | O40: {=_xlfn.TEXTJOIN(", ",TRUE,_xlfn._xlws.FILTER(Tabla28[[#All],[PARTE]],ISNUMBER(SEARCH(Tabla28[[#All],[PCLAVE2]],Tabla8[[#This Row],[DESCRIPCION DE TRABAJO]])),""))} -> Mds | P40: =IFERROR(LEFT(O40, FIND(",", O40)-1), O40) -> Mds | Q40: =IFERROR(IF(ISERROR(FIND(",", O40, FIND(",", O40)+1)), RIGHT(O40, LEN(O40)-FIND(",", O40)-1), MID(O40, FIND(",", O40)+2, FIND(",", O40, FIND(",", O40)+1)-FIND(",", O40)-2)), "") | R40: =IFERROR(RIGHT(O40, LEN(O40)-FIND(",", O40, FIND(",", O40)+1)-1), "") | S40: {=_xlfn.TEXTJOIN(", ",TRUE,_xlfn._xlws.FILTER(Tabla29[[#All],[PARTE]],ISNUMBER(SEARCH(Tabla29[[#All],[PCLAVE3]],Tabla8[[#This Row],[DESCRIPCION DE TRABAJO]])),""))} | T40: =IF(AND(Tabla8[[#This Row],[PIEZA]]="",Tabla8[[#This Row],[PARTE]]=""),"VACIO","OK") -> OK | U40: =+CONCATENATE(WEEKNUM(Tabla8[[#This Row],[FECHA]]),"-",YEAR(Tabla8[[#This Row],[FECHA]])) -> 2-2026
